<?xml version='1.0' encoding='utf-8'?>
<testsuites xmlns:a="http://microsoft.com/schemas/VisualStudio/TeamTest/2006" xmlns:b="http://microsoft.com/schemas/VisualStudio/TeamTest/2010">
  <testsuite name="MSTestSuite" tests="11" failures="5" errors="0" skipped="1">
    <testcase classname="DotnetTests.XUnitTests.CalculatorTests" name="Timeout_Test" time="0.1084258"/>
    <testcase classname="DotnetTests.XUnitTests.CalculatorTests" name="Passing_Test" time="0.0001365"/>
    <testcase classname="DotnetTests.XUnitTests.CalculatorTests" name="Should be even number(i: 3)" time="0.0006537">
      <failure message="Assert.True() Failure&#13;&#10;Expected: True&#13;&#10;Actual:   False">Assert.True() Failure&#13;
Expected: True&#13;
Actual:   False   at DotnetTests.XUnitTests.CalculatorTests.Theory_With_Custom_Name(Int32 i) in C:\Users\Michal\Workspace\dorny\test-reporter\reports\dotnet\DotnetTests.XUnitTests\CalculatorTests.cs:line 67</failure>
    </testcase>
    <testcase classname="DotnetTests.XUnitTests.CalculatorTests" name="Skipped_Test" time="0.001">
      <skipped message=""/>
    </testcase>
    <testcase classname="DotnetTests.XUnitTests.CalculatorTests" name="Custom Name" time="0.0001371"/>
    <testcase classname="DotnetTests.XUnitTests.CalculatorTests" name="Should be even number(i: 2)" time="0.0000097"/>
    <testcase classname="DotnetTests.XUnitTests.CalculatorTests" name="Exception_In_TargetTest" time="0.0008377">
      <failure message="System.DivideByZeroException : Attempted to divide by zero.">System.DivideByZeroException : Attempted to divide by zero.   at DotnetTests.Unit.Calculator.Div(Int32 a, Int32 b) in C:\Users\Michal\Workspace\dorny\test-reporter\reports\dotnet\DotnetTests.Unit\Calculator.cs:line 9&#13;
   at DotnetTests.XUnitTests.CalculatorTests.Exception_In_TargetTest() in C:\Users\Michal\Workspace\dorny\test-reporter\reports\dotnet\DotnetTests.XUnitTests\CalculatorTests.cs:line 33</failure>
    </testcase>
    <testcase classname="DotnetTests.XUnitTests.CalculatorTests" name="Exception_In_Test" time="0.0025175">
      <failure message="System.Exception : Test">System.Exception : Test   at DotnetTests.XUnitTests.CalculatorTests.Exception_In_Test() in C:\Users\Michal\Workspace\dorny\test-reporter\reports\dotnet\DotnetTests.XUnitTests\CalculatorTests.cs:line 39</failure>
    </testcase>
    <testcase classname="DotnetTests.XUnitTests.CalculatorTests" name="Failing_Test" time="0.0038697">
      <failure message="Assert.Equal() Failure&#13;&#10;Expected: 3&#13;&#10;Actual:   2">Assert.Equal() Failure&#13;
Expected: 3&#13;
Actual:   2   at DotnetTests.XUnitTests.CalculatorTests.Failing_Test() in C:\Users\Michal\Workspace\dorny\test-reporter\reports\dotnet\DotnetTests.XUnitTests\CalculatorTests.cs:line 27</failure>
    </testcase>
    <testcase classname="DotnetTests.XUnitTests.CalculatorTests" name="Is_Even_Number(i: 2)" time="0.0000078"/>
    <testcase classname="DotnetTests.XUnitTests.CalculatorTests" name="Is_Even_Number(i: 3)" time="0.0004141">
      <failure message="Assert.True() Failure&#13;&#10;Expected: True&#13;&#10;Actual:   False">Assert.True() Failure&#13;
Expected: True&#13;
Actual:   False   at DotnetTests.XUnitTests.CalculatorTests.Is_Even_Number(Int32 i) in C:\Users\Michal\Workspace\dorny\test-reporter\reports\dotnet\DotnetTests.XUnitTests\CalculatorTests.cs:line 59</failure>
    </testcase>
  </testsuite>
</testsuites>
